Workbook

Sheet Diagnóstico
A1: DIAGNÓSTICO DO GARGALO OCULTO
A2: O mapa que revela por que seu faturamento parou de crescer
A3: COMO PREENCHER:
A4: 1) Em cada item, abra o menu suspenso na coluna "Sua avaliação" e escolha uma das 3 opções.
A5: 2) A pontuação é calculada automaticamente. Não precisa mexer na coluna "Pontos".
A6: 3) Ao terminar, vá até a aba "Resultado" para ver o radar e o seu gargalo oculto.
A8: PROCESSOS — cada item "satisfatório" vale 10 pts · Como o trabalho realmente acontece no dia a dia.
A9: # | B9: Item avaliado | C9: Sua avaliação | D9: Pontos
A10: 1 | B10: Os principais processos do negócio estão documentados. | D10: =IF($C10="Existe e é satisfatório",10,IF($C10="Existe, mas não é satisfatório",5,0))
A11: 2 | B11: Quando aparecem problemas, não somente apagamos incêndios — as causas são investigadas. | D11: =IF($C11="Existe e é satisfatório",10,IF($C11="Existe, mas não é satisfatório",5,0))
A12: 3 | B12: Os colaboradores têm clareza da missão, visão, valores, políticas, ações e objetivos. | D12: =IF($C12="Existe e é satisfatório",10,IF($C12="Existe, mas não é satisfatório",5,0))
A13: 4 | B13: Existem indicadores mapeados e monitorados. | D13: =IF($C13="Existe e é satisfatório",10,IF($C13="Existe, mas não é satisfatório",5,0))
A14: 5 | B14: Acontecem reuniões de alinhamento das tarefas com as equipes (gerenciamento da rotina). | D14: =IF($C14="Existe e é satisfatório",10,IF($C14="Existe, mas não é satisfatório",5,0))
A15: 6 | B15: Os colaboradores sabem exatamente o que fazer, pois existe um manual (ou documento) de cultura/orientações. | D15: =IF($C15="Existe e é satisfatório",10,IF($C15="Existe, mas não é satisfatório",5,0))
A16: 7 | B16: São realizados planos de ação para alcançar as metas/objetivos. | D16: =IF($C16="Existe e é satisfatório",10,IF($C16="Existe, mas não é satisfatório",5,0))
A17: 8 | B17: Existe uma dose adequada de planejamento antes da execução. | D17: =IF($C17="Existe e é satisfatório",10,IF($C17="Existe, mas não é satisfatório",5,0))
A18: 9 | B18: Temos uma mentalidade de melhoria contínua, utilizando a ferramenta PDCA. | D18: =IF($C18="Existe e é satisfatório",10,IF($C18="Existe, mas não é satisfatório",5,0))
A19: 10 | B19: Temos um organograma documentado e compartilhado com todos. | D19: =IF($C19="Existe e é satisfatório",10,IF($C19="Existe, mas não é satisfatório",5,0))
B20: SUBTOTAL — Processos (máximo 100) | C20: =SUM(D10:D19)&" / 100" | D20: =SUM(D10:D19)
A22: RESULTADOS — cada item "satisfatório" vale 20 pts · O que o negócio efetivamente entrega e mede.
A23: # | B23: Item avaliado | C23: Sua avaliação | D23: Pontos
A24: 1 | B24: A margem de lucro do negócio é mensurada e está em nível satisfatório. | D24: =IF($C24="Existe e é satisfatório",20,IF($C24="Existe, mas não é satisfatório",10,0))
A25: 2 | B25: A satisfação do cliente é mensurada e está em nível satisfatório. | D25: =IF($C25="Existe e é satisfatório",20,IF($C25="Existe, mas não é satisfatório",10,0))
A26: 3 | B26: A satisfação do colaborador é mensurada e está em nível satisfatório. | D26: =IF($C26="Existe e é satisfatório",20,IF($C26="Existe, mas não é satisfatório",10,0))
A27: 4 | B27: Existe remuneração atrelada ao desempenho (ao menos para as pessoas-chave) na organização. | D27: =IF($C27="Existe e é satisfatório",20,IF($C27="Existe, mas não é satisfatório",10,0))
A28: 5 | B28: A taxa de crescimento da empresa geralmente é maior que a esperada/planejada. | D28: =IF($C28="Existe e é satisfatório",20,IF($C28="Existe, mas não é satisfatório",10,0))
B29: SUBTOTAL — Resultados (máximo 100) | C29: =SUM(D24:D28)&" / 100" | D29: =SUM(D24:D28)
A31: SISTEMA DE GESTÃO — cada item "satisfatório" vale 20 pts · O leme estratégico que conduz a empresa.
A32: # | B32: Item avaliado | C32: Sua avaliação | D32: Pontos
A33: 1 | B33: É feito planejamento anualmente para curto, médio e longo prazo (1 a 3 ou 1 a 5 anos). | D33: =IF($C33="Existe e é satisfatório",20,IF($C33="Existe, mas não é satisfatório",10,0))
A34: 2 | B34: Os sistemas de informação (softwares) são adequados para o nível de maturidade/momento da empresa. | D34: =IF($C34="Existe e é satisfatório",20,IF($C34="Existe, mas não é satisfatório",10,0))
A35: 3 | B35: As metas são bem estabelecidas, sempre contemplando: indicador, prazo e valor. | D35: =IF($C35="Existe e é satisfatório",20,IF($C35="Existe, mas não é satisfatório",10,0))
A36: 4 | B36: Existe por parte dos donos/líderes alocação de tempo adequado para a parte estratégica da empresa. | D36: =IF($C36="Existe e é satisfatório",20,IF($C36="Existe, mas não é satisfatório",10,0))
A37: 5 | B37: Os indicadores são acompanhados e comunicados para a equipe. | D37: =IF($C37="Existe e é satisfatório",20,IF($C37="Existe, mas não é satisfatório",10,0))
B38: SUBTOTAL — Sistema de Gestão (máximo 100) | C38: =SUM(D33:D37)&" / 100" | D38: =SUM(D33:D37)
A40: PESSOAS — cada item "satisfatório" vale 10 pts · Time, liderança e cultura que sustentam o crescimento.
A41: # | B41: Item avaliado | C41: Sua avaliação | D41: Pontos
A42: 1 | B42: Existem ações de comunicação interna/endomarketing para gerar engajamento nas pessoas. | D42: =IF($C42="Existe e é satisfatório",10,IF($C42="Existe, mas não é satisfatório",5,0))
A43: 2 | B43: O processo de recrutamento, seleção e integração é adequadamente conduzido. | D43: =IF($C43="Existe e é satisfatório",10,IF($C43="Existe, mas não é satisfatório",5,0))
A44: 3 | B44: Os colaboradores recebem feedback periódico sobre seu desempenho. | D44: =IF($C44="Existe e é satisfatório",10,IF($C44="Existe, mas não é satisfatório",5,0))
...

Sheet Listas
A1: Existe e é satisfatório
A2: Existe, mas não é satisfatório
A3: Não existe

Sheet Textos
A1: Dimensão | B1: Título | C1: Diagnóstico | E1: Mín | F1: Faixa | G1: Resumo
A2: Processos | B2: Seu gargalo oculto está nos PROCESSOS | C2: Seu negócio cresceu, mas a operação ainda depende de você e de alguns "heróis". Sem processos documentados e rotina gerenciada, cada novo cliente adiciona caos em vez de lucro. O faturamento parou de crescer porque a empresa não consegue entregar mais sem quebrar. | E2: 0 | F2: Sobrevivência | G2: A empresa funciona na base do esforço pessoal e da reação. Pequenos ajustes estruturais geram saltos rápidos.
A3: Resultados | B3: Seu gargalo oculto está nos RESULTADOS | C3: Você está ocupado o tempo todo, mas não sabe ao certo se está lucrando. Sem medir margem, satisfação de cliente e de equipe, você pilota a empresa no escuro. O faturamento estagnou porque você otimiza o que sente, não o que os números mostram. | E3: 40 | F3: Organização | G3: Você saiu do caos, mas um gargalo específico segura o crescimento do restante. Destravá-lo leva ao próximo patamar.
A4: Sistema de Gestão | B4: Seu gargalo oculto está no SISTEMA DE GESTÃO | C4: Falta o leme estratégico. Sem planejamento, metas claras (indicador, prazo e valor) e tempo dedicado a pensar o negócio, a empresa vive presa no operacional e apenas reage ao mercado. O crescimento travou porque ninguém está, de fato, pilotando o longo prazo. | E4: 70 | F4: Escala | G4: A base está sólida. O gargalo é fino e específico — o ajuste que torna o crescimento previsível e sustentável.
A5: Pessoas | B5: Seu gargalo oculto está nas PESSOAS | C5: Seu time é seu maior ativo — e, hoje, seu maior gargalo. Sem uma liderança que delega, engaja e desenvolve, tudo volta para o dono e a empresa não escala além da capacidade de uma única pessoa. O faturamento parou porque você é, ao mesmo tempo, o motor e o limite do negócio.

Sheet Resultado
A1: RESULTADO DO DIAGNÓSTICO
A4: Dimensão | B4: Atual (%) | C4: Desejado (%) | D4: Prazo
A5: Processos | B5: =Diagnóstico!D20 | C5: 100
A6: Resultados | B6: =Diagnóstico!D29 | C6: 100
A7: Sistema de Gestão | B7: =Diagnóstico!D38 | C7: 100
A8: Pessoas | B8: =Diagnóstico!D52 | C8: 100
A29: SUA LEITURA AUTOMÁTICA
A30: Gargalo oculto | B30: =INDEX(A5:A8,MATCH(MIN(B5:B8),B5:B8,0))
A31: Título | B31: =IFERROR(VLOOKUP(B30,Textos!$A$2:$C$5,2,FALSE),"")
A32: Diagnóstico | B32: =IFERROR(VLOOKUP(B30,Textos!$A$2:$C$5,3,FALSE),"")
A33: Maturidade geral | B33: =ROUND(AVERAGE(B5:B8),0)&"% — "&IFERROR(VLOOKUP(ROUND(AVERAGE(B5:B8),0),Textos!$E$2:$G$4,2,TRUE),"")
A34: O que fazer agora | B34: =IFERROR(VLOOKUP(ROUND(AVERAGE(B5:B8),0),Textos!$E$2:$G$4,3,TRUE),"")
A36: Agora você sabe ONDE travou. A próxima pergunta vale seu próximo salto: COMO destravar?
